<?xml version='1.0' encoding='utf-8'?>
<robot name="panda">
<link name="world"/>

<joint name="world_to_panda" type="fixed">
  <parent link="world"/>
  <child link="panda_link0"/>
  <origin xyz="0 0 0" rpy="0 0 0"/>
</joint>

  <link name="panda_link0">
    <inertial>
      <mass value="100.0" />
      <origin xyz="0 0 -0.05" rpy="0 0 0" />
      <inertia ixx="1.0" ixy="0" ixz="0" iyy="1.0" iyz="0" izz="1.0" />
    </inertial>
    <visual>
      <geometry>
        <mesh filename="file:///workspace/install/panda_gz_moveit/share/panda_gz_moveit/meshes/collision/link0.obj" />
      </geometry>
      <material name="panda_white" />
    </visual>
    <collision>
      <geometry>
        <mesh filename="file:///workspace/install/panda_gz_moveit/share/panda_gz_moveit/meshes/collision/link0.obj" />
      </geometry>
      <material name="panda_white" />
      <surface>
        <friction>
          <ode>
            <mu>100.0</mu>
            <mu2>100.0</mu2>
          </ode>
        </friction>
      </surface>
    </collision>
  </link>

  <link name="panda_link1">
    <inertial><mass value="4.0" /><origin xyz="0 0 0" rpy="0 0 0" /><inertia ixx="0.01" ixy="0" ixz="0" iyy="0.01" iyz="0" izz="0.01" /></inertial>
    <visual>
      <geometry>
        <mesh filename="file:///workspace/install/panda_gz_moveit/share/panda_gz_moveit/meshes/collision/link1.obj" />
      </geometry>
      <material name="panda_white" />
    </visual>
    <collision>
      <geometry>
        <mesh filename="file:///workspace/install/panda_gz_moveit/share/panda_gz_moveit/meshes/collision/link1.obj" />
      </geometry>
      <material name="panda_white" />
    </collision>
  </link>

  <joint name="panda_joint1" type="revolute">
    <safety_controller k_position="100.0" k_velocity="40.0" soft_lower_limit="-2.8973" soft_upper_limit="2.8973" />
    <origin rpy="0 0 0" xyz="0 0 0.333" />
    <parent link="panda_link0" />
    <child link="panda_link1" />
    <axis xyz="0 0 1" />
    <limit effort="87" lower="-2.9671" upper="2.9671" velocity="2.1750" />
    <dynamics damping="10.0" friction="1.0"/>
  </joint>

  <link name="panda_link2">
    <inertial><mass value="4.0" /><origin xyz="0 0 0" rpy="0 0 0" /><inertia ixx="0.01" ixy="0" ixz="0" iyy="0.01" iyz="0" izz="0.01" /></inertial>
    <visual>
      <geometry>
        <mesh filename="file:///workspace/install/panda_gz_moveit/share/panda_gz_moveit/meshes/collision/link2.obj" />
      </geometry>
      <material name="panda_white" />
    </visual>
    <collision>
      <geometry>
        <mesh filename="file:///workspace/install/panda_gz_moveit/share/panda_gz_moveit/meshes/collision/link2.obj" />
      </geometry>
      <material name="panda_white" />
    </collision>
  </link>

  <joint name="panda_joint2" type="revolute">
    <safety_controller k_position="100.0" k_velocity="40.0" soft_lower_limit="-1.7628" soft_upper_limit="1.7628" />
    <origin rpy="-1.57079632679 0 0" xyz="0 0 0" />
    <parent link="panda_link1" />
    <child link="panda_link2" />
    <axis xyz="0 0 1" />
    <limit effort="87" lower="-1.8326" upper="1.8326" velocity="2.1750" />
    <dynamics damping="10.0" friction="1.0"/>
  </joint>

  <link name="panda_link3">
    <inertial><mass value="3.0" /><origin xyz="0 0 0" rpy="0 0 0" /><inertia ixx="0.01" ixy="0" ixz="0" iyy="0.01" iyz="0" izz="0.01" /></inertial>
    <visual>
      <geometry>
        <mesh filename="file:///workspace/install/panda_gz_moveit/share/panda_gz_moveit/meshes/collision/link3.obj" />
      </geometry>
      <material name="panda_white" />
    </visual>
    <collision>
      <geometry>
        <mesh filename="file:///workspace/install/panda_gz_moveit/share/panda_gz_moveit/meshes/collision/link3.obj" />
      </geometry>
      <material name="panda_white" />
    </collision>
  </link>

  <joint name="panda_joint3" type="revolute">
    <safety_controller k_position="100.0" k_velocity="40.0" soft_lower_limit="-2.8973" soft_upper_limit="2.8973" />
    <origin rpy="1.57079632679 0 0" xyz="0 -0.316 0" />
    <parent link="panda_link2" />
    <child link="panda_link3" />
    <axis xyz="0 0 1" />
    <limit effort="87" lower="-2.9671" upper="2.9671" velocity="2.1750" />
    <dynamics damping="10.0" friction="1.0"/>
  </joint>

  <link name="panda_link4">
    <inertial><mass value="3.0" /><origin xyz="0 0 0" rpy="0 0 0" /><inertia ixx="0.01" ixy="0" ixz="0" iyy="0.01" iyz="0" izz="0.01" /></inertial>
    <visual>
      <geometry>
        <mesh filename="file:///workspace/install/panda_gz_moveit/share/panda_gz_moveit/meshes/collision/link4.obj" />
      </geometry>
      <material name="panda_white" />
    </visual>
    <collision>
      <geometry>
        <mesh filename="file:///workspace/install/panda_gz_moveit/share/panda_gz_moveit/meshes/collision/link4.obj" />
      </geometry>
      <material name="panda_white" />
    </collision>
  </link>

  <joint name="panda_joint4" type="revolute">
    <safety_controller k_position="100.0" k_velocity="40.0" soft_lower_limit="-3.0718" soft_upper_limit="-0.0698" />
    <origin rpy="1.57079632679 0 0" xyz="0.0825 0 0" />
    <parent link="panda_link3" />
    <child link="panda_link4" />
    <axis xyz="0 0 1" />
    <limit effort="87" lower="-3.1416" upper="0.0" velocity="2.1750" />
    <dynamics damping="10.0" friction="1.0"/>
  </joint>

  <link name="panda_link5">
    <inertial><mass value="2.0" /><origin xyz="0 0 0" rpy="0 0 0" /><inertia ixx="0.01" ixy="0" ixz="0" iyy="0.01" iyz="0" izz="0.01" /></inertial>
    <visual>
      <geometry>
        <mesh filename="file:///workspace/install/panda_gz_moveit/share/panda_gz_moveit/meshes/collision/link5.obj" />
      </geometry>
      <material name="panda_white" />
    </visual>
    <collision>
      <geometry>
        <mesh filename="file:///workspace/install/panda_gz_moveit/share/panda_gz_moveit/meshes/collision/link5.obj" />
      </geometry>
      <material name="panda_white" />
    </collision>
  </link>

  <joint name="panda_joint5" type="revolute">
    <safety_controller k_position="100.0" k_velocity="40.0" soft_lower_limit="-2.8973" soft_upper_limit="2.8973" />
    <origin rpy="-1.57079632679 0 0" xyz="-0.0825 0.384 0" />
    <parent link="panda_link4" />
    <child link="panda_link5" />
    <axis xyz="0 0 1" />
    <limit effort="12" lower="-2.9671" upper="2.9671" velocity="2.6100" />
    <dynamics damping="10.0" friction="1.0"/>
  </joint>

  <link name="panda_link6">
    <inertial><mass value="2.0" /><origin xyz="0 0 0" rpy="0 0 0" /><inertia ixx="0.01" ixy="0" ixz="0" iyy="0.01" iyz="0" izz="0.01" /></inertial>
    <visual>
      <geometry>
        <mesh filename="file:///workspace/install/panda_gz_moveit/share/panda_gz_moveit/meshes/collision/link6.obj" />
      </geometry>
      <material name="panda_white" />
    </visual>
    <collision>
      <geometry>
        <mesh filename="file:///workspace/install/panda_gz_moveit/share/panda_gz_moveit/meshes/collision/link6.obj" />
      </geometry>
      <material name="panda_white" />
    </collision>
  </link>

  <joint name="panda_joint6" type="revolute">
    <safety_controller k_position="100.0" k_velocity="40.0" soft_lower_limit="-0.0175" soft_upper_limit="3.7525" />
    <origin rpy="1.57079632679 0 0" xyz="0 0 0" />
    <parent link="panda_link5" />
    <child link="panda_link6" />
    <axis xyz="0 0 1" />
    <limit effort="12" lower="-0.0873" upper="3.8223" velocity="2.6100" />
    <dynamics damping="10.0" friction="1.0"/>
  </joint>

  <link name="panda_link7">
    <inertial><mass value="1.0" /><origin xyz="0 0 0" rpy="0 0 0" /><inertia ixx="0.01" ixy="0" ixz="0" iyy="0.01" iyz="0" izz="0.01" /></inertial>
    <visual>
      <geometry>
        <mesh filename="file:///workspace/install/panda_gz_moveit/share/panda_gz_moveit/meshes/collision/link7.obj" />
      </geometry>
      <material name="panda_white" />
    </visual>
    <collision>
      <geometry>
        <mesh filename="file:///workspace/install/panda_gz_moveit/share/panda_gz_moveit/meshes/collision/link7.obj" />
      </geometry>
      <material name="panda_white" />
    </collision>
  </link>

  <joint name="panda_joint7" type="revolute">
    <safety_controller k_position="100.0" k_velocity="40.0" soft_lower_limit="-2.8973" soft_upper_limit="2.8973" />
    <origin rpy="1.57079632679 0 0" xyz="0.088 0 0" />
    <parent link="panda_link6" />
    <child link="panda_link7" />
    <axis xyz="0 0 1" />
    <limit effort="12" lower="-2.9671" upper="2.9671" velocity="2.6100" />
    <dynamics damping="10.0" friction="1.0"/>
  </joint>

  <link name="panda_link8">
    <inertial><mass value="0.01" /><origin xyz="0 0 0" rpy="0 0 0" /><inertia ixx="0.01" ixy="0" ixz="0" iyy="0.01" iyz="0" izz="0.01" /></inertial>
  </link>

  <joint name="panda_joint8" type="fixed">
    <origin rpy="0 0 0" xyz="0 0 0.107" />
    <parent link="panda_link7" />
    <child link="panda_link8" />
    <axis xyz="0 0 0" />
  </joint>

  <joint name="panda_hand_joint" type="fixed">
    <parent link="panda_link8" />
    <child link="panda_hand" />
    <origin rpy="0 0 -0.785398163397" xyz="0 0 0" />
  </joint>

  <link name="panda_hand">
    <inertial><mass value="0.8" /><origin xyz="0 0 0" rpy="0 0 0" /><inertia ixx="0.01" ixy="0" ixz="0" iyy="0.01" iyz="0" izz="0.01" /></inertial>
    <visual>
      <geometry>
        <mesh filename="file:///workspace/install/panda_gz_moveit/share/panda_gz_moveit/meshes/collision/hand.obj" />
      </geometry>
      <material name="panda_white" />
    </visual>
    <collision>
      <geometry>
        <mesh filename="file:///workspace/install/panda_gz_moveit/share/panda_gz_moveit/meshes/collision/hand.obj" />
      </geometry>
      <material name="panda_white" />
    </collision>
  </link>

  <link name="panda_leftfinger">
    <inertial><mass value="0.05" /><origin xyz="0 0 0" rpy="0 0 0" /><inertia ixx="0.01" ixy="0" ixz="0" iyy="0.01" iyz="0" izz="0.01" /></inertial>
    <visual>
      <geometry>
        <mesh filename="file:///workspace/install/panda_gz_moveit/share/panda_gz_moveit/meshes/collision/finger.obj" />
      </geometry>
      <material name="panda_white" />
    </visual>
    <collision>
      <geometry>
        <mesh filename="file:///workspace/install/panda_gz_moveit/share/panda_gz_moveit/meshes/collision/finger.obj" />
      </geometry>
      <material name="panda_white" />
    </collision>
  </link>

  <link name="panda_rightfinger">
    <inertial><mass value="0.05" /><origin xyz="0 0 0" rpy="0 0 0" /><inertia ixx="0.01" ixy="0" ixz="0" iyy="0.01" iyz="0" izz="0.01" /></inertial>
    <visual>
      <origin rpy="0 0 3.14159265359" xyz="0 0 0" />
      <geometry>
        <mesh filename="file:///workspace/install/panda_gz_moveit/share/panda_gz_moveit/meshes/collision/finger.obj" />
      </geometry>
      <material name="panda_white" />
    </visual>
    <collision>
      <origin rpy="0 0 3.14159265359" xyz="0 0 0" />
      <geometry>
        <mesh filename="file:///workspace/install/panda_gz_moveit/share/panda_gz_moveit/meshes/collision/finger.obj" />
      </geometry>
      <material name="panda_white" />
    </collision>
  </link>

  <joint name="panda_finger_joint1" type="prismatic">
    <parent link="panda_hand" />
    <child link="panda_leftfinger" />
    <origin rpy="0 0 0" xyz="0 0 0.0584" />
    <axis xyz="0 1 0" />
    <limit effort="20" lower="0.0" upper="0.04" velocity="0.2" />
    <dynamics damping="5.0" friction="0.5"/>
  </joint>

  <joint name="panda_finger_joint2" type="prismatic">
    <parent link="panda_hand" />
    <child link="panda_rightfinger" />
    <origin rpy="0 0 0" xyz="0 0 0.0584" />
    <axis xyz="0 -1 0" />
    <limit effort="20" lower="0.0" upper="0.04" velocity="0.2" />
    <dynamics damping="5.0" friction="0.5"/>
    <mimic joint="panda_finger_joint1" />
  </joint>

  <material name="panda_white">
    <color rgba="1. 1. 1. 1." />
  </material>
  <gazebo>
    <plugin filename="gz-sim-joint-state-publisher-system"
            name="gz::sim::systems::JointStatePublisher">
      <topic>/world/panda_grasp_world/model/panda/joint_state</topic>
      <joint_name>panda_joint1</joint_name>
      <joint_name>panda_joint2</joint_name>
      <joint_name>panda_joint3</joint_name>
      <joint_name>panda_joint4</joint_name>
      <joint_name>panda_joint5</joint_name>
      <joint_name>panda_joint6</joint_name>
      <joint_name>panda_joint7</joint_name>
    </plugin>
  </gazebo>

<gazebo>
  <plugin filename="gz-sim-joint-position-controller-system"
          name="gz::sim::systems::JointPositionController">
    <joint_name>panda_joint1</joint_name>
    <topic>/panda_joint1_cmd</topic>
    <p_gain>1000</p_gain> <i_gain>0.1</i_gain>   <d_gain>10</d_gain>    <i_max>1</i_max>
    <i_min>-1</i_min>
    <cmd_max>1000</cmd_max>
    <cmd_min>-1000</cmd_min>
  </plugin>
</gazebo>

<gazebo>
  <plugin filename="gz-sim-joint-position-controller-system"
          name="gz::sim::systems::JointPositionController">
    <joint_name>panda_joint2</joint_name>
    <topic>/panda_joint2_cmd</topic>
    <p_gain>1000</p_gain> <i_gain>0.1</i_gain>   <d_gain>10</d_gain>    <i_max>1</i_max>
    <i_min>-1</i_min>
    <cmd_max>1000</cmd_max>
    <cmd_min>-1000</cmd_min>
  </plugin>
</gazebo>
<gazebo>
  <plugin filename="gz-sim-joint-position-controller-system"
          name="gz::sim::systems::JointPositionController">
    <joint_name>panda_joint3</joint_name>
    <topic>/panda_joint3_cmd</topic>
    <p_gain>1000</p_gain> <i_gain>0.1</i_gain>   <d_gain>10</d_gain>    <i_max>1</i_max>
    <i_min>-1</i_min>
    <cmd_max>1000</cmd_max>
    <cmd_min>-1000</cmd_min>
  </plugin>
</gazebo>
<gazebo>
    <plugin filename="gz-sim-joint-position-controller-system"
            name="gz::sim::systems::JointPositionController">
      <joint_name>panda_joint4</joint_name>
      <topic>/panda_joint4_cmd</topic>
      <p_gain>1000</p_gain> <i_gain>0.1</i_gain> <d_gain>10</d_gain>
      <i_max>1</i_max> <i_min>-1</i_min>
      <cmd_max>1000</cmd_max> <cmd_min>-1000</cmd_min>
    </plugin>
  </gazebo>

  <gazebo>
    <plugin filename="gz-sim-joint-position-controller-system"
            name="gz::sim::systems::JointPositionController">
      <joint_name>panda_joint5</joint_name>
      <topic>/panda_joint5_cmd</topic>
      <p_gain>1000</p_gain> <i_gain>0.1</i_gain> <d_gain>10</d_gain>
      <i_max>1</i_max> <i_min>-1</i_min>
      <cmd_max>1000</cmd_max> <cmd_min>-1000</cmd_min>
    </plugin>
  </gazebo>

  <gazebo>
    <plugin filename="gz-sim-joint-position-controller-system"
            name="gz::sim::systems::JointPositionController">
      <joint_name>panda_joint6</joint_name>
      <topic>/panda_joint6_cmd</topic>
      <p_gain>1000</p_gain> <i_gain>0.1</i_gain> <d_gain>10</d_gain>
      <i_max>1</i_max> <i_min>-1</i_min>
      <cmd_max>1000</cmd_max> <cmd_min>-1000</cmd_min>
    </plugin>
  </gazebo>

  <gazebo>
    <plugin filename="gz-sim-joint-position-controller-system"
            name="gz::sim::systems::JointPositionController">
      <joint_name>panda_joint7</joint_name>
      <topic>/panda_joint7_cmd</topic>
      <p_gain>1000</p_gain> <i_gain>0.1</i_gain> <d_gain>10</d_gain>
      <i_max>1</i_max> <i_min>-1</i_min>
      <cmd_max>1000</cmd_max> <cmd_min>-1000</cmd_min>
    </plugin>
  </gazebo>

  <gazebo>
    <plugin filename="gz-sim-joint-position-controller-system"
            name="gz::sim::systems::JointPositionController">
      <joint_name>panda_finger_joint1</joint_name>
      <topic>/panda_finger_joint1_cmd</topic>
      <p_gain>50</p_gain> <i_gain>0.0</i_gain> <d_gain>5</d_gain>
      <cmd_max>100</cmd_max> <cmd_min>-100</cmd_min>
    </plugin>
  </gazebo>

  <gazebo>
    <plugin filename="gz-sim-joint-position-controller-system"
            name="gz::sim::systems::JointPositionController">
      <joint_name>panda_finger_joint2</joint_name>
      <topic>/panda_finger_joint2_cmd</topic>
      <p_gain>50</p_gain> <i_gain>0.0</i_gain> <d_gain>5</d_gain>
      <cmd_max>100</cmd_max> <cmd_min>-100</cmd_min>
    </plugin>
  </gazebo>

</robot>